<?xml version='1.0'?>
<robot name="robot" xmlns:xacro="http://www.ros.org/wiki/xacro">

  <xacro:include filename="$(find obstacle_avoidance_simulation)/urdf/robot.gazebo" />
  <link name="robot_footprint"></link>


<gazebo reference="left_wheel">
    <material>Gazebo/Red</material>
</gazebo>

<gazebo reference="right_wheel">
    <material>Gazebo/Red</material>
</gazebo>

<gazebo reference="chassis">
    <material>Gazebo/Black</material>
</gazebo>

<link name='chassis'>
    <pose>0 0 0.1 0 0 0</pose>

    <inertial>
      <mass value="15.0"/>
      <origin xyz="0.0 0 0" rpy=" 0 0 0"/>
      <inertia
          ixx="0.1" ixy="0" ixz="0"
          iyy="0.1" iyz="0"
          izz="0.1"
      />
    </inertial>

    <collision name='collision'>
	     <!--origin xyz="0 0 0" rpy=" 0 0 0"/-->
      <origin xyz="0 0 0" rpy=" 0 0 0"/>
      <geometry>
        <!--box size=".4 .2 .1"/-->
		<cylinder radius="0.1" length="0.1"/>
      </geometry>
    </collision>

    <visual name='chassis_visual'>
      <!--origin xyz="0 0 0" rpy=" 0 0 0"/-->
	  <origin xyz="0 0 0" rpy=" 0 0 0"/>
      <geometry>
        <!--box size=".4 .2 .1"/-->
		<cylinder radius="0.1" length="0.1"/>
      </geometry>
    </visual>


    <collision name='back_caster_collision'>
      <origin xyz="-0.05 0 -0.05" rpy=" 0 0 0"/>
      <geometry>
        <sphere radius="0.0299"/>
      </geometry>
    </collision>

    <visual name='back_caster_visual'>
      <origin xyz="-0.05 0 -0.05" rpy=" 0 0 0"/>
      <geometry>
        <sphere radius="0.03"/>
      </geometry>
    </visual>

    <collision name='front_caster_collision'>
      <origin xyz="0.05 0 -0.05" rpy=" 0 0 0"/>
      <geometry>
        <sphere radius="0.0299"/>
      </geometry>
    </collision>

    <visual name='front_caster_visual'>
      <origin xyz="0.05 0 -0.05" rpy=" 0 0 0"/>
      <geometry>
        <sphere radius="0.03"/>
      </geometry>
    </visual>

  </link>

<link name='left_wheel'>
    <inertial>
      <mass value="5.0"/>
      <origin xyz="0.0 0 0" rpy=" 0 0 0"/>
      <inertia
          ixx="0.1" ixy="0" ixz="0"
          iyy="0.1" iyz="0"
          izz="0.1"
      />
    </inertial>

    <visual name='left_wheel_visual'>
      <origin xyz="0 0 0" rpy=" 0 1.5707 1.5707"/>
      <geometry>
        <cylinder radius="0.03" length="0.01"/>
      </geometry>
    </visual>

    <collision name='left_wheel_collision'>
      <origin xyz="0 0 0" rpy=" 0 1.5707 1.5707"/>
      <geometry>
        <cylinder radius="0.03" length="0.01"/>
      </geometry>
    </collision>

 </link>

<link name='right_wheel'>
    <inertial>
      <mass value="5.0"/>
      <origin xyz="0.0 0 0" rpy=" 0 0 0"/>
      <inertia
          ixx="0.1" ixy="0" ixz="0"
          iyy="0.1" iyz="0"
          izz="0.1"
      />
    </inertial>

    <visual name='right_wheel_visual'>
      <origin xyz="0 0 0" rpy=" 0 1.5707 1.5707"/>
      <geometry>
        <cylinder radius="0.03" length="0.01"/>
      </geometry>
    </visual>

    <collision name='right_wheel_collision'>
      <origin xyz="0 0 0" rpy=" 0 1.5707 1.5707"/>
      <geometry>
        <cylinder radius="0.03" length="0.01"/>
      </geometry>
    </collision>
 </link>

  <link name='hokuyo'>
    <inertial>
      <mass value="1e-5"/>
      <origin xyz="0 0 0" rpy=" 0 0 0"/>
      <inertia
	  ixx="1e-6" ixy="0" ixz="0"
	  iyy="1e-6" iyz="0"
	  izz="1e-6"
      />
    </inertial>

    <visual name='hokuyo_visual'>
      <origin xyz="0 0 0" rpy=" 0 0 0"/>
      <geometry>
	<mesh filename="package://obstacle_avoidance_simulation/meshes/hokuyo.dae"/>
      </geometry>
    </visual>

    <collision name='hokuyo_collision'>
      <origin xyz="0 0 0" rpy=" 0 0 0"/>
      <geometry>
	<box size=".1 .1 .1"/>
      </geometry>
    </collision>
  </link>

<!-- Joints -->

  <joint name="robot_footprint_joint" type="fixed">
    <origin xyz="0 0 0" rpy="0 0 0" />
    <parent link="robot_footprint"/>
    <child link="chassis" />
  </joint>

   <joint type="continuous" name="left_wheel_hinge">
    <origin xyz="0 0.07 -0.05" rpy="0 0 0"/>
    <child link="left_wheel"/>
    <parent link="chassis"/>
    <axis xyz="0 1 0" rpy="0 0 0"/>
    <limit effort="10000" velocity="1000"/>
    <dynamics damping="1.0" friction="1.0"/>
  </joint>

<joint type="continuous" name="right_wheel_hinge">
    <origin xyz="0 -0.07 -0.05" rpy="0 0 0"/>
    <child link="right_wheel"/>
    <parent link="chassis"/>
    <axis xyz="0 1 0" rpy="0 0 0"/>
    <limit effort="10000" velocity="1000"/>
    <dynamics damping="1.0" friction="1.0"/>
  </joint>

<joint type="fixed" name="hokuyo_joint">
    <origin xyz="0 0 .08" rpy="0 0 0"/>
    <child link="hokuyo"/>
    <parent link="chassis"/>
    <axis xyz="0 1 0" rpy="0 0 0"/>
  </joint>

</robot>
